Workbook
Name Compute_P0: Assumptions!$G$14
Name Deal_WACC_premium: Assumptions!$G$46
Name ErrorTolerance: Checks!$C$2
Name Facility_capex_MW: Assumptions!$G$10
Name Facility_salvage_pct: Assumptions!$G$18
Name Floor_ext_high: Assumptions!$D$68
Name Floor_ext_low: Assumptions!$D$67
Name FloorTolerance: Assumptions!$D$69
Name GPU_life: Assumptions!$G$16
Name GPU_salvage_pct: Assumptions!$G$19
Name Hours_per_year: Assumptions!$F$28
Name Insurance_rate: Assumptions!$F$30
Name IT_load_MW: Assumptions!$G$21
Name List_Country: Assumptions!$B$50:$B$54
Name List_ReviewStatus: Assumptions!$B$58:$B$60
Name List_Scenario: Assumptions!$D$9:$F$9
Name OM_fixed: Assumptions!$G$17
Name Paid_occupancy: Assumptions!$G$15
Name Price_decline: Assumptions!$G$65
Name Price_floor: Assumptions!$G$66
Name Prop_tax_abatement: Assumptions!$F$31
Name Ramp_yr1: Assumptions!$F$32
Name Ramp_yr2: Assumptions!$F$33
Name Risk_free: Assumptions!$F$39
Name Shadow_carbon_price: Assumptions!$F$40
Name TTP_disp_hi: 'Interconnection Queue'!$F$4
Name TTP_disp_lo: 'Interconnection Queue'!$F$5
Name Unit_scale: Assumptions!$F$29

Sheet Cover
A1: 100 MW Data-Center Unit-Economics Model (Norway, Saudi Arabia, United States, Ireland, India) | C1: =IF(Checks!$C$4>0,"MODEL IN ERROR","checks OK") -> checks OK
A2: Finding: power is a trivial cost (~1–2% of revenue) at today's price, but it crosses to material once a long grid queue erodes the entry price to the floor.
A3: Owner: Henry Dalby · Status: PUBLISH · Periods 0–19 (annual) · Single workbook, no external links
A4: Thesis: with calendar-coupled compute-price erosion, time-to-power reorderds viability and destroys value in slow-queue geographies. Purpose: compare the viability of a 100 MW AI data center across 5 countries from an auditable per-MW asset P&L (per-period DCF).
A5: Intended users: the analyst (Henry) first; auditable by a finance professional on first open.
A6: What this IS: an indicative, comparative unit-economics model ranking five countries on AI-data-centre viability. · What it is FOR: the relative ranking and the drivers that move it (queue length, power, WACC, price erosion). · What it is NOT: a bankable, financing-grade valuation of any single project — absolute NPVs are directional. See the Limitations tab.
A7: Format key (River / FAST convention)
A8: Blue font | B8: Data origin — an input you may change, or a value linked in from another sheet
A9: Black font | B9: Calculated on this sheet
A10: Red font | B10: Output consumed elsewhere, or a check / status flag
A11: Only unlocked cells are editable | B11: Sheets are protected; blue input cells on Assumptions / Buildout / Review are the only editable cells
A12: Brackets = negative, dash = zero | B12: Standard finance display; units column on every calc row
A13: Tab colours by section | B13: Navy = structural/navigation · amber = inputs · steel-blue = calculations · green = outputs · gold = checks
A14: Contents
A15: Model map | B15: how it fits together
A16: Limitations | B16: scope qualifiation--read before the results
A17: Sources | B17: source data graded by confidence key
A18: GPU Specs | B18: primary spec data per single accelerator. B200
A19: Compute Price Data | B19: getDeploying B200 panel + Silicon Data SDB200RT index are the primary basis
A20: Interconnection Queue | B20: US data with observed dispersion calculation
A21: Power Build-up | B21: wholesale grid/firming prices
A22: WACC Build-up | B22: USD-nominal cost of capital decomposed
A23: Assumptions | B23: distilled drivers + country data Table (last in inputs)
A24: Capex Stack | B24: shell/fit-out/GPU/networking per MW
A25: Unit Economics | B25: per-MW build block + external anchor
A26: Buildout Schedule | B26: deployment records Table
... A48: Reconciliation: Calculations (active drill) = Country Engine (all countries × deals, per period) = Comparison, to the dollar; Checks!C4 = 0 with zero error cells across every scenario × deal × country state. | B48: country records Table

Sheet Model map
A1: Model map — how this workbook fits together | C1: =IF(Checks!$C$4>0,"MODEL IN ERROR","checks OK") -> checks OK
A2: Orient once, navigate anywhere. Three toggles drive everything; data flows one direction; reconciliations keep it honest.
D3: Workbook status | E3: =IF(Checks!$C$4>0,"MODEL IN ERROR","checks OK") -> checks OK
A4: 1 · The three toggles (set on Assumptions)
B5: Toggle | C5: Set on | D5: Options | E5: What it drives
B6: Scenario | C6: Assumptions!B4 | D6: Bear / Base / Bull | E6: Delivered power, time-to-power, WACC (all countries)
B7: Country | C7: Assumptions!B5 | D7: Norway/US/India/Ireland/Saudi | E7: Which country Calculations & Country detail present
B8: Deal type | C8: Assumptions!B7 | D8: Contracted / Merchant | E8: Occupancy, WACC premium
A10: 2 · Data flow — one direction, no circularity
B11: Sourcing tabs (GPU Specs, Compute Price Data, Interconnection Queue, Power/WACC Build-ups) → Assumptions (distilled drivers, last in inputs)
B12: ↓
B13: Capex Stack → Unit Economics (per-MW) → Buildout Schedule (facility-capex draw) → Calculations (per-period DCF)
B14: ↓
B15: Comparison (all 5 countries, closed-form) → Country detail → Scenario Grid → Checks
B16: Energy Security (WEC Trilemma) is a FENCED labelled-implication tab — it does NOT feed the P&L.
A19: 3 · Reconciliations (all on Checks; C4 must = 0)
B20: • Two-engine tie: Calculations per-period NPV = Comparison closed-form NPV (active country)
B21: • Roll-up tie: Unit Economics per-MW × IT load = Calculations facility + GPU capex
B22: • Buildout tie: DCF facility-capex draw (Σ per-period) reconciles to the facility capex total; draw weights sum to 1
B23: • Scenario Grid tie: active-country grid NPV = Calculations NPV
B24: • EXTERNAL ANCHORS: capex/MW in $30–50m band; revenue/MW/yr in $15–40m band (sourced)
A26: 4 · Key drivers (High materiality)
B27: • Compute price ($/GPU-hr) — largest NPV lever
B28: • GPU+IT capex & density — physically coupled across chip generations
B29: • Time-to-power (yr) — the sharpest country-varying energy lever
B30: • Cost of capital — unlevered hurdle rate (WACC proxy) — country-varying
B31: • IT load (MW) — scale
A33: 5 · Disclosed modelling choices
B34: • Country Engine net-FCF is one long row (~228 chars) — but FLAT (2 IFs, not nested) and single-purpose. Deliberate compact-engine tradeoff: the 15-block Country Engine stays readable by inlining the cash-flow aggregation into one line; the fully-decomposed, one-row-per-component version lives on Calculations.
B35: • Reference/build-up tabs (Power Build-up, WACC Build-up, GPU Specs, Compute Price Data) are RECONCILED to Assumptions by check (Checks r22/r24/r25), not live-linked. Assumptions holds the authoritative hardcodes; the build-ups show the derivation. Interconnection Queue is the live-linked source: US TTP (median/p75/p25) plus the dispersion ratios that set the other four countries’ TTP bands.

Sheet Limitations
A1: Limitations & scope — read before the results | C1: =IF(Checks!$C$4>0,"MODEL IN ERROR","checks OK") -> checks OK
A2: This is an INDICATIVE, comparative unit-economics model for ranking five countries — not a bankable, financing-grade valuation. It is deliberately simple; the limitations below are disclosed by design, not oversights. Absolute NPVs carry the uncertainty of all inputs; the country RANKING is the robust output.
A4: # | B4: Limitation | C4: Effect on the results | D4: How it is handled / disclosed
A5: 1 | B5: Indicative, not bankable | C5: Unlevered, single-hold; absolute NPV is directional, not a financing valuation. | D5: Use for cross-country ranking, not underwriting. Stated on Cover / Model map. No equity valuation or demand forecasting.
A6: 2 | B6: Compute-price decline & floor are PROJECTIONS | C6: B200 has not yet entered its decline; the 20%/yr erosion and $2.50 floor drive the economics. | D6: Calibrated to the realized H100 lifecycle; flagged as estimates in Sources (r34/r39-41) and on the Price Floor tab.
A7: 3 | B7: Single-hold liquidation framing | C7: One GPU cycle then exit; real operators may re-tenant, which would raise returns. | D7: Deliberate simplification; disclosed. Re-tenanting removed to keep the model auditable.
A8: 4 | B8: Grid carbon NOT priced | C8: A pure-$/MWh ranking would silently favour cheap-but-dirty grids. | D8: Grid carbon intensity (gCO2/kWh) shown as a second lens on Comparison (r42), explicitly NOT in the NPV.
A9: 5 | B9: Ireland CRU Large-Energy-User policy (late-2025) | C9: New DCs >10 MVA must self-generate 100% flexible + source 80% new renewables in 6 yr — a capex/feasibility burden not priced. Effect on results is unambiguously negative for Ireland: it does NOT change the Base/Bull ranking (Ireland is already last), but Ireland's Bear ‘least-bad’ rank (1st — its price is already at the floor, so it has the least erosion downside) is overstated and would fall if the CRU generation/storage capex and ~6-yr approval timing were costed. Deliberately not modelled, to avoid false precision. Source: CRU/EirGrid Dec-2025 (Sources r14/r30). | D9: Disclosed; it makes Ireland (already last on NPV) harder still. Model UNDERSTATES Ireland difficulty.
A10: 6 | B10: Water / cooling-water cost not separately modelled | C10: Material in hot climates (India, Saudi); modestly understates their opex. | D10: Disclosed caveat; folded into O&M at a country-flat rate.
A11: 7 | B11: US export controls / chip access (status as of Aug 2026) | C11: Ranking assumes lawful Blackwell (B200/GB200) procurement — presumption-of-denial by default. US/Norway/Ireland: unrestricted (domestic/allied). Saudi: conditional — approved via HUMAIN (Nov-2025) under RTE security/reporting + cap. India: licensed/capped (trusted-partner quota, ~270k H100-eq in 2026). No modelled country is blocked, but Saudi/India access is conditional. | D11: Boundary condition, NOT priced in the NPV; the ranking is conditional on access holding. Regime is transactional/volatile (Diffusion Rule rescinded May-2025). Sources: US Commerce Nov-2025; BIS/IISS 2025-26. Developed in the article.
A12: 8 | B12: Single 100 MW reference facility | C12: Per-MW unit economics; not a portfolio, staged-build, or financing model. | D12: Scale is a normalisation, not a forecast. Disclosed.
A13: 9 | B13: Networking fabric, GPU attrition, decommissioning | C13: Not separately line-itemed; minor understatement of cost. | D13: Folded into capex/O&M or omitted; disclosed. Immaterial to the ranking.
A14: 10 | B14: Delivered power is zone/market-dependent | C14: US = ERCOT basis (PJM 2–3× higher); Norway = blended NO zones. | D14: Disclosed on Power Build-up; delivered price validated vs observed industrial all-in.
A15: 11 | B15: Point-in-time sources | C15: Prices, tariffs, and queues as of ~Aug 2026 in a fast-moving market. | D15: Every input dated & graded on Sources; refresh before re-use.
... A23: 19 | B23: Time-to-power band methodology | C23: Non-US TTP dispersion is transferred from the US LBNL distribution (the only observed one); country medians are regulator-sourced. Ireland’s upper tail is likely fatter than the transferred IQR (CRU policy). | D23: US bands observed (LBNL); non-US bands = median × US IQR. Disclosed on Assumptions & Sources r51.
B25: Chip-access feasibility screen — export-control status by country (as of ~Aug 2026; verify current BIS rules before relying). Blackwell/B200 default = licence-required; named operator/end-user, supply route and basis below. Sources: [39][44][45].
B26: Country | C26: Chip-access status | D26: Named operator / end-user | E26: Supply route | F26: Basis / citation
B27: Norway | C27: Permitted — no US licence (EEA/NATO; Country Group A) | D27: nScale — Glomfjord AI data centre (hydro) | E27: NVIDIA → OEM → nScale (EEA) | F27: BIS EAR §742.6 [44]; operators/routes [45]
B28: United States | C28: Permitted — domestic (no export) | D28: US hyperscalers / neoclouds (e.g., CoreWeave) | E28: Domestic build | F28: BIS EAR [44] (no export)
B29: India | C29: Licence-required — approvals flowing (not Tier 1) | D29: Reliance (1 GW Gujarat); Tata Communications; Yotta (20,736 Blackwell Ultra) | E29: NVIDIA → OEM → Indian operator under US licence | F29: Export controls [39]; framework [44]; operators [45]; DPDP Act 2023
B30: Ireland | C30: Permitted — EU/Tier 1 (grid connection, not chips, is the binding gate) | D30: EU hyperscaler cloud (Dublin) | E30: NVIDIA → OEM → EU operator | F30: BIS EAR [44]; Ireland CRU policy [11]
B31: Saudi Arabia | C31: Licence-required — conditionally AUTHORISED Nov-2025 (end-user-specific) | D31: HUMAIN (PIF): up to 35,000 GB300 authorised; plan ~600k accelerators | E31: NVIDIA → OEM → HUMAIN; BIS security/reporting conditions | F31: US Commerce/BIS 19-Nov-2025 [39][44]
B32: Implication: “lawful chip access” is not uniform across the five. Norway/US/Ireland are unrestricted; India and Saudi require US licences (Saudi’s is conditional and specific to HUMAIN). Any country’s NPV rank is contingent on the named operator holding a valid licence/authorisation and meeting BIS security conditions — the model still holds chip access constant, so the India/Saudi ranks are conditional.

Sheet ▸ INPUTS
A1: ▸ INPUTS

Sheet Sources
A1: Sources | D1: =IF(Checks!$C$4>0,"MODEL IN ERROR","checks OK") -> checks OK
A2: High = primary/operator/regulator · Med = specialist aggregator · Low = disclosed judgment.
A3: # | B3: Input | C3: Value / note | D3: Named source | E3: Vintage | F3: Source confidence | G3: Source link
A4: 1 | B4: Facility build capex | C4: $17m/MW Base (band 13–24) | D4: AI liquid-cooled 2026 (ModulEdge/Epoch) | E4: 2026 | F4: Med | G4: https://epoch.ai/data-insights/ai-datacenter-cost-breakdown
A5: 2 | B5: GPU + IT capex | C5: $42,000/single B200 GPU deployed (band $35–56k: DGX B200 ~$35–40k/GPU; HGX B200 ~$56k; card $40–50k) | D5: Mercatus B200 server price; Silicon Analysts B200 cost breakdown; NVIDIA DGX B200 | E5: 2026 | F5: Med | G5: https://www.mercatus-ai.com/blog/b200-server-price
A6: 3 | B6: GPUs per MW | C6: ~600 GPU/MW (B200 1000W; HGX node ~13.3kW/8 → 1.667 kW/GPU) | D6: NVIDIA B200 / HGX B200 datasheet | E6: 2025-26 | F6: Med | G6: https://www.nvidia.com/en-us/data-center/hgx/
A7: 4 | B7: PUE (country-varying) | C7: NO 1.15 / IE 1.20 / US 1.30 / SA 1.45 / IN 1.50 | D7: LBNL 2024 US DC Energy Usage Report | E7: 2024-26 | F7: Med | G7: https://eta.lbl.gov/publications/2024-lbnl-data-center-energy-usage-report
A8: 5 | B8: Compute price | C8: $5.70/GPU-hr Base P0 (committed 1-yr, today); band $4.00–$9.00 Bear→Bull; erodes ~20%/yr to full-cost floor | D8: Silicon Data SDB200RT index; getDeploying B200 committed panel (45 listings, 7-Aug-2026) | E8: 2026 | F8: High | G8: https://www.silicondata.com/products/silicon-index
A9: 6 | B9: Utilization / occupancy | C9: 88% contracted / 70% merchant | D9: CBRE DC vacancy ~1.4%, ~74% pre-leased | E9: 2026 | F9: Low | G9: https://www.cbre.com/insights/reports/global-data-center-trends-2026
A10: 7 | B10: GPU economic life | C10: 5 yr (Bear 3 / Bull 6) | D10: Hyperscaler 10-K (Amazon 5yr, Meta 5.5yr) | E10: 2025-26 | F10: Med | G10: https://thecuberesearch.com/298-breaking-analysis-resetting-gpu-depreciation
A11: 8 | B11: Norway power / TTP / WACC | C11: $52/MWh · 2.0yr · 6.34% | D11: SSB; Statnett 2025; Damodaran 2026 | E11: 2025-26 | F11: Med | G11: https://www.ssb.no/en/energi-og-industri
A12: 9 | B12: US power / TTP / WACC | C12: $60/MWh · 4.5yr · 6.34% | D12: TTP=LBNL queue (uploaded, thru-2025): recent-cohort (online≥2019) median 4.5yr, p25 3.2/p75 5.8, N=1,297 operational; WACC per build-up | E12: 2025-26 | F12: High | G12: https://emp.lbl.gov/queues
A13: 10 | B13: India power / TTP / WACC | C13: $95/MWh · 3.0yr · 7.84% USD-nom | D13: GlobalPetrolPrices; Deccan Chronicle Jan-26; Damodaran | E13: 2025-26 | F13: Med | G13: https://www.deccanchronicle.com/business/latest/what-india-can-learn-from-the-us-about-data-centres-1973592
A14: 11 | B14: Ireland power / TTP / WACC | C14: $150/MWh · 6.0yr · 6.84% USD-nom | D14: CRU/EirGrid Dec-2025 policy; Damodaran | E14: 2025-26 | F14: Med | G14: https://www.cru.ie/
A15: 12 | B15: Saudi power / TTP / WACC | C15: $48/MWh · 2.0yr · 6.84% USD-nom | D15: SEC tariff; SERA framework (GT Jan-26); Damodaran | E15: 2025-26 | F15: Med | G15: https://www.gtlaw.com/en/insights/2026/1/saudi-arabias-data-centre-expansion-regulatory-framework-and-strategic-considerations
... A51: 48 | B51: GPU rental price — Azure H100 (mature-generation analog) | C51: Azure H100 SXM by tier (on-demand / reserved 1-3-5yr / spot); context analog for the B200 lifecycle — feeds no P&L. | D51: Microsoft Azure Retail Prices API | E51: 2026 | F51: High | G51: https://prices.azure.com/api/retail/prices
A54: Source-reliability grading key (col E)
A55: Grades the RELIABILITY OF THE SOURCE behind each input — NOT statistical confidence. Ordinal source-quality rating (tier × vintage × directness). Quantitative uncertainty is carried SEPARATELY by the input bands (Bear/Base/Bull) and the Sensitivity tornado.
A56: High | B56: Primary source (official statistics / regulator / grid operator / IEA / EIA / Ember / Damodaran / vendor datasheet), current vintage (2025–26), direct measure — used as published.
A57: Med-High | B57: Primary market data + a primary reference model (e.g. sovereign 10-yr yield + Damodaran country-risk premium). Stronger than Med, short of a single direct measure.
A58: Med | B58: Primary source needing adjustment/interpolation, OR a reputable specialist aggregator (SemiAnalysis / CBRE / JLL / Lazard), current vintage.
A59: Low | B59: Single secondary source, proxy, disclosed judgment residual, or definitional uncertainty. Directional and flagged as such (e.g. merchant occupancy, idle-shell holding cost, WACC project premium, power firming residual).

Sheet GPU Specs
A1: GPU Specs — per accelerator (NVIDIA datasheets) · modelled generation: NVIDIA B200 (Blackwell, HGX) | C1: =IF(Checks!$C$4>0,"MODEL IN ERROR","checks OK") -> checks OK
A2: Primary spec data per single accelerator. B200 (HGX 8-GPU) is the modelled generation; H100 and GB200 NVL72 shown for reference/continuity.
A3: REFERENCE TAB — density (col F, B200 row) reconciled to Assumptions G12 by Checks r22; not live-linked.
A4: Specs — per accelerator (NVIDIA datasheets)
A5: GPU (accelerator) | B5: Power (W) | C5: Memory (GB) | D5: Per rack/board | E5: kW/rack | F5: Implied GPU/MW | G5: Source
A6: H100 SXM5 — prior-gen reference | B6: 700 | C6: 80 | D6: 8 (HGX) | E6: — | F6: — | G6: [17]
A7: B200 (HGX) — MODELLED | B7: 1000 | C7: 192 | D7: 8 (HGX) | E7: 13.33 | F7: =ROUND(1000/(E7/8),0) -> 600 | G7: [17]
A8: GB200 (Blackwell, NVL72) — frontier reference (not modelled) | B8: 1200 | C8: 192 | D8: 72 (NVL72) | E8: 120 | F8: =ROUND(1000/(E8/72),0) -> 600 | G8: [17]
A9: B200 implied density = 1 MW ÷ (HGX node 13.3 kW ÷ 8 GPU = 1.667 kW/GPU) ≈ 600 GPU/MW → ties to Assumptions density (G12).

Sheet Compute Price Data
A1: Compute Price Data — $/GPU-hr evidence (NVIDIA B200, Blackwell) | C1: =IF(Checks!$C$4>0,"MODEL IN ERROR","checks OK") -> checks OK
A2: getDeploying B200 panel (7-Aug-2026, ~110 listings) + Silicon Data SDB200RT index are the primary basis. Azure H100 surface below is retained as the mature-generation analog (lifecycle & floor template).
A3: REFERENCE TAB — observed $/GPU-hr envelope; the P0 inputs are checked against it (Checks r35/r36); not live-linked.
A4: H100 SXM by tier — mature-generation analog (AVERAGEIFS over the raw Azure table; continuity/floor template) [48]
A5: Tier | B5: n (COUNTIFS) | C5: Mean $/GPU-hr | D5: Source
A6: On-demand | B6: =COUNTIFS(AzurePrice[Tier],"On-demand") -> 24 | C6: =AVERAGEIFS(AzurePrice[$/GPU-hr],AzurePrice[Tier],"On-demand") -> 16.053333 | D6: [48]
A7: Reserved 1yr | B7: =COUNTIFS(AzurePrice[Tier],"Reserved 1yr") -> 24 | C7: =AVERAGEIFS(AzurePrice[$/GPU-hr],AzurePrice[Tier],"Reserved 1yr") -> 10.26125 | D7: [48]
A8: Reserved 3yr | B8: =COUNTIFS(AzurePrice[Tier],"Reserved 3yr") -> 24 | C8: =AVERAGEIFS(AzurePrice[$/GPU-hr],AzurePrice[Tier],"Reserved 3yr") -> 7.0366667 | D8: [48]
A9: Reserved 5yr | B9: =COUNTIFS(AzurePrice[Tier],"Reserved 5yr") -> 24 | C9: =AVERAGEIFS(AzurePrice[$/GPU-hr],AzurePrice[Tier],"Reserved 5yr") -> 6.4125 | D9: [48]
A10: Spot | B10: =COUNTIFS(AzurePrice[Tier],"Spot") -> 24 | C10: =AVERAGEIFS(AzurePrice[$/GPU-hr],AzurePrice[Tier],"Spot") -> 2.9666667 | D10: [48]
A12: getDeploying neocloud B200 by tier (7-Aug-2026) + Silicon Data SDB200RT [19]
A13: Billing | B13: Listings | C13: Avg $/GPU-hr | D13: Source
A14: On-demand | B14: 35 | C14: 6.85 | D14: [18][19]
A15: Reserved / committed 1yr | B15: 45 | C15: 5.71 | D15: [18][19]
A16: Custom contract | B16: 7 | C16: 3.49 | D16: [18][19]
A17: Spot | B17: 20 | C17: 3.6 | D17: [18][19]
A19: Envelope for the compute-price check ($/GPU-hr) — B200
A20: Observed floor (B200 committed/spot low) | C20: 3.35 | D20: [34]
A21: Realized ceiling (B200 on-demand high) | C21: 8.2 | D21: [19]
A22: Model Base $5.70 (committed) must sit inside [floor 3.35, ceiling 8.20] Floor band source [34].
A24: Azure raw price surface (H100, region × tier) — mature-generation analog reference
A25: Region | B25: Tier | C25: $/GPU-hr
A26: australiaeast | B26: On-demand | C26: 17.82
A27: canadacentral | B27: On-demand | C27: 14.75
A28: centralus | B28: On-demand | C28: 15.12
A29: eastus | B29: On-demand | C29: 12.29
A30: eastus2 | B30: On-demand | C30: 12.29
A31: japaneast | B31: On-demand | C31: 17.82
A32: japanwest | B32: On-demand | C32: 19.05
A33: koreacentral | B33: On-demand | C33: 16.59
A34: northcentralus | B34: On-demand | C34: 14.75
A35: polandcentral | B35: On-demand | C35: 15.98
A36: southafricanorth | B36: On-demand | C36: 21.08
A37: southafricawest | B37: On-demand | C37: 23.33
... A145: westus3 | B145: Spot | C145: 2.27
A147: Source: Azure Retail Prices API (prices.azure.com/api/retail/prices), official Microsoft list pricing, no auth. Clickable link on the Sources tab. getDeploying neocloud summary retained for the realized tier.

Sheet Interconnection Queue
A1: US Interconnection Queue — LBNL, recent operational cohort (uploaded raw) | C1: =IF(Checks!$C$4>0,"MODEL IN ERROR","checks OK") -> checks OK
A2: 1297 operational US projects (online ≥2019) with a valid queue→online duration, from LBNL's 38,201-request dataset. US time-to-power (Bear/Base/Bull) is the LIVE median / p75 / p25 of the Duration column below. Source: US time-to-power [25]; dispersion transfer to non-US [46].
A3: Base = MEDIAN duration (yr) | C3: =MEDIAN(QueueTable[Duration (yr)]) -> 4.5 | E3: Dispersion transfer (US-observed IQR → applied to non-US medians):
A4: Bear = 75th pct (slower, yr) | C4: =PERCENTILE(QueueTable[Duration (yr)],0.75) -> 5.83 | E4: p75 / median (hi) | F4: =C4/C3 -> 1.2955556
A5: Bull = 25th pct (faster, yr) | C5: =PERCENTILE(QueueTable[Duration (yr)],0.25) -> 3.17 | E5: p25 / median (lo) | F5: =C5/C3 -> 0.70444444
A6: q_id | B6: State | C6: Type | D6: Queue yr | E6: Online yr | F6: Duration (yr)
A7: 1010 | B7: CA | C7: Wind | D7: 2014.2 | E7: 2022.2 | F7: 8
A8: 1016 | B8: CA | C8: Gas | D8: 2014.2 | E8: 2019.2 | F8: 5
A9: 1027 | B9: CA | C9: Battery | D9: 2014.2 | E9: 2023.7 | F9: 9.42
A10: 1036 | B10: CA | C10: Solar | D10: 2014.2 | E10: 2020.8 | F10: 6.58
A11: 1053 | B11: AZ | C11: Solar | D11: 2014.2 | E11: 2019.8 | F11: 5.5
A12: 1097 | B12: CA | C12: Battery | D12: 2015.2 | E12: 2024.5 | F12: 9.25
A13: 1103 | B13: CA | C13: Solar | D13: 2015.2 | E13: 2021.1 | F13: 5.83
A14: 1109 | B14: CA | C14: Battery | D14: 2015.2 | E14: 2023.6 | F14: 8.33
A15: 1111 | B15: CA | C15: Battery | D15: 2015.2 | E15: 2022.2 | F15: 6.92
A16: 1117 | B16: CA | C16: Solar | D16: 2015.2 | E16: 2021.9 | F16: 6.67
A17: 1136 | B17: CA | C17: Solar | D17: 2015.2 | E17: 2023.7 | F17: 8.42
A18: 1170 | B18: CA | C18: Battery | D18: 2015.2 | E18: 2025.2 | F18: 10
... A1210: 26INR0694 | B1210: TX | C1210: Oil | D1210: 2025.4 | E1210: 2025.8 | F1210: 0.42
A1211: 22INR0468 | C1211: Battery | D1211: 2021.1 | E1211: 2025.6 | F1211: 4.5
A1212: 22INR0540 | C1212: Battery | D1212: 2021.5 | E1212: 2025.8 | F1212: 4.25
A1213: 23INR0007 | C1213: Solar+Battery | D1213: 2019.9 | E1213: 2025.6 | F1213: 5.67
A1214: 23INR0287 | C1214: Battery | D1214: 2021.3 | E1214: 2025.7 | F1214: 4.33
A1215: 23INR0619 | C1215: Battery | D1215: 2023.4 | E1215: 2025.2 | F1215: 1.75
A1216: 24INR0460 | C1216: Battery | D1216: 2023 | E1216: 2025.7 | F1216: 2.67
A1217: 24INR0596 | C1217: Battery | D1217: 2023.4 | E1217: 2025.6 | F1217: 2.17
A1218: 25INR0223 | C1218: Gas | D1218: 2022.7 | E1218: 2025.6 | F1218: 2.92
A1219: 25INR0467 | C1219: Battery | D1219: 2023.4 | E1219: 2025.6 | F1219: 2.17
A1220: 25INR0777 | C1220: Other | D1220: 2025.4 | E1220: 2025.8 | F1220: 0.33
A1221: 26INR0666 | C1221: Other | D1221: 2025.4 | E1221: 2025.7 | F1221: 0.25
A1222: 26INR0674 | C1222: Other | D1222: 2025.4 | E1222: 2025.7 | F1222: 0.25
... A1241: 373 | C1241: Battery | D1241: 2019.8 | E1241: 2020.5 | F1241: 0.75
A1242: 505 | B1242: NY | C1242: Wind | D1242: 2015.4 | E1242: 2023.8 | F1242: 8.33
A1243: IC-237 | C1243: Nuclear | D1243: 2010.2 | E1243: 2024.2 | F1243: 14.08
A1244: 1 | C1244: Solar | D1244: 2016.6 | E1244: 2020.1 | F1244: 3.5
A1245: 61 | C1245: Battery | D1245: 2019.6 | E1245: 2021.9 | F1245: 2.33
A1246: 77 | C1246: Solar | D1246: 2021.4 | E1246: 2022.9 | F1246: 1.5
A1247: 10230 | C1247: Gas | D1247: 2017.2 | E1247: 2020.9 | F1247: 3.75
A1248: 17116 | C1248: Solar | D1248: 2016.8 | E1248: 2020.9 | F1248: 4.08
A1249: 9409 | C1249: Solar | D1249: 2016.8 | E1249: 2020.8 | F1249: 4
...

Sheet Power Build-up
A1: Delivered Power Build-up — wholesale + delivery split, validated vs observed industrial all-in ($/MWh) | C1: =IF(Checks!$C$4>0,"MODEL IN ERROR","checks OK") -> checks OK
A2: Delivered price (col E) = the Assumptions country-table Base, externally validated against an observed industrial all-in price (col G). Wholesale (col C) is sourced; the grid/T&D+firming line (col D) is now an ILLUSTRATIVE SPLIT (delivered − wholesale), not a claim. US = ERCOT basis; Norway = blended NO zones; Saudi = regulated tariff.
A3: REFERENCE TAB — reconciled to the Assumptions country table (delivered power) by Checks r24; not live-linked. Assumptions holds the authoritative hardcodes.
B4: Country | C4: Wholesale avg | D4: Grid/T&D + firming (illustrative split = delivered − wholesale) | E4: Delivered (build-up) | F4: Wholesale source | G4: Observed industrial all-in ($/MWh) | H4: Observed-price source | I4: Notes / basis
B5: Norway | C5: 40 | D5: =Assumptions!$D$50-C5 -> 12 | E5: =C5+D5 -> 52 | F5: [22] | G5: 55 | H5: [37] | I5: IEA Nordics H1-2025 ~$40/MWh (SSB/Nord Pool); delivered = wholesale + grid/T&D + firming
B6: United States | C6: 30 | D6: =Assumptions!$D$51-C6 -> 30 | E6: =C6+D6 -> 60 | F6: [22] | G6: 62 | H6: [37] | I6: IEA/EIA ERCOT 2025 ~$30/MWh; delivered $60 = ERCOT + ~$30 grid/T&D
B7: India | C7: 49 | D7: =Assumptions!$D$52-C7 -> 46 | E7: =C7+D7 -> 95 | F7: [23] | G7: 92 | H7: [37] | I7: IEX DAM 2025 ~₹4.2/kWh ≈ $49/MWh
B8: Ireland | C8: 95 | D8: =Assumptions!$D$53-C8 -> 55 | E8: =C8+D8 -> 150 | F8: [22] | G8: 155 | H8: [37] | I8: IEA EU H1-2025 ~$90/MWh; IE higher (SEMOpx)
B9: Saudi Arabia | C9: 48 | D9: =Assumptions!$D$54-C9 -> 0 | E9: =C9+D9 -> 48 | F9: [22] | G9: 50 | H9: [37] | I9: Regulated SEC/SERA industrial tariff ~$48/MWh
B11: Delivered (col E) ties to the Assumptions country table (Base) — arithmetic verified on Checks r24 — and is cross-checked against an independent observed industrial all-in price (col G, Checks r17). The wholesale/delivery split (cols C/D) is illustrative decomposition, not the source of the number.
A13: External validation — max |delivered − observed industrial all-in| ÷ observed (flag if > 20%): | C13: =MAX(ABS(E5-G5)/G5, ABS(E6-G6)/G6, ABS(E7-G7)/G7, ABS(E8-G8)/G8, ABS(E9-G9)/G9) -> 0.054545455 | D13: =--(C13>0.2) -> 0

Sheet WACC Build-up
A1: WACC Build-up (unlevered project hurdle rate) — USD risk-free + country-risk premium + project premium. This is an unlevered hurdle rate used as a WACC proxy; NOT a levered WACC (no debt cost, beta, ERP or capital structure). | C1: =IF(Checks!$C$4>0,"MODEL IN ERROR","checks OK") -> checks OK
A2: USD-nominal cost of capital decomposed. Risk-free = US 10-yr less US default spread (Damodaran method); CRP from Damodaran Jan-2026 (sourced); the project/asset premium is a disclosed judgment residual. Reconciles to the country table (Base).
A3: REFERENCE TAB — reconciled to the Assumptions country-table WACC by Checks r25; not live-linked. Assumptions holds the authoritative hardcodes.
B4: USD risk-free (linked from Assumptions input) | E4: =Risk_free -> 0.04236 | F4: Risk-free linked from Assumptions [21] (FRED DGS10). Project premium = disclosed judgment.
B5: Country | C5: Risk-free | D5: CRP (Damodaran) [20] | E5: Project premium (disclosed judgment) | F5: WACC (build-up) | G5: Source
B6: Norway | C6: =$E$4 -> 0.04236 | D6: 0 | E6: 0.021 | F6: =C6+D6+E6 -> 0.06336 | G6: [20][21]
B7: United States | C7: =$E$4 -> 0.04236 | D7: 0.0023 | E7: 0.0187 | F7: =C7+D7+E7 -> 0.06336 | G7: [20][21]
B8: India | C8: =$E$4 -> 0.04236 | D8: 0.0285 | E8: 0.0075 | F8: =C8+D8+E8 -> 0.07836 | G8: [20][21]
B9: Ireland | C9: =$E$4 -> 0.04236 | D9: 0.0078 | E9: 0.0182 | F9: =C9+D9+E9 -> 0.06836 | G9: [20][21]
B10: Saudi Arabia | C10: =$E$4 -> 0.04236 | D10: 0.0078 | E10: 0.0182 | F10: =C10+D10+E10 -> 0.06836 | G10: [20][21]
B12: WACC (col F) ties to the Assumptions country table (Base) — reconciliation verified on Checks. Risk-free & CRP are High-reliability (FRED / Damodaran); the project premium is a disclosed judgment residual (Low).
B13: India's project premium is smallest (0.75pp) — its frozen 8.0% WACC sits only modestly above the sourced rf+CRP floor of 7.25%.

Sheet Assumptions
A1: Assumptions | C1: =IF(Checks!$C$4>0,"MODEL IN ERROR","checks OK") -> checks OK
A2: Every input. The sourcing/build-up tabs before this one (GPU Specs, GPU Price Index, Power/WACC Build-ups) evidence the key drivers; those ties are verified on Checks. BLUE = input you may change; the Active column feeds the engine. Col K = Materiality (High = defend cold). Energy Security block (rows 79+) is a LABELLED IMPLICATION and does NOT feed the P&L.
A4: Scenario (all countries) | B4: Base
A5: Country (drill-down only) | B5: Norway
A6: Energy-source analysis | B6: → see EnergyDynamics tab
A7: Deal type (Contracted/Merchant) | B7: Contracted
A9: # | B9: Driver | C9: Units | D9: Bear | E9: Base | F9: Bull | G9: Active | H9: Source | I9: Comment
A10: 1 | B10: Facility build capex (ex-interconnect) | C10: $m/MW | D10: 24 | E10: 17 | F10: 13 | G10: =INDEX(D10:F10,MATCH($B$4,$D$9:$F$9,0)) -> 17 | H10: [1] | I10: -
A11: 2 | B11: GPU + IT capex (per single GPU) | C11: $/GPU | D11: 50000 | E11: 42000 | F11: 35000 | G11: =INDEX(D11:F11,MATCH($B$4,$D$9:$F$9,0)) -> 42000 | H11: [2] | I11: 'GPU'=one single B200 accelerator (~600/MW, ~$42k/GPU). Basis: DGX B200 ~$35–40k/GPU; HGX B200 ~$56k; bare card $40–50k; Base $42k = DGX-class + IT share.
A12: 3 | B12: GPUs per MW (single accelerator) | C12: #/MW | D12: 600 | E12: 600 | F12: 600 | G12: =INDEX(D12:F12,MATCH($B$4,$D$9:$F$9,0)) -> 600 | H12: [3] | I12: B200 1000W TDP; HGX 8-GPU node ~13.3kW at IT level (GPU+CPU+NVSwitch+networking) → 1 MW ÷ 1.667 kW/GPU ≈ 600 GPU/MW.
A13: 4 | B13: PUE (per usage effectiveness) | C13: % | D13: =INDEX($M$50:$M$54,MATCH($B$5,$B$50:$B$54,0)) -> 1.15 | E13: =INDEX($M$50:$M$54,MATCH($B$5,$B$50:$B$54,0)) -> 1.15 | F13: =INDEX($M$50:$M$54,MATCH($B$5,$B$50:$B$54,0)) -> 1.15 | G13: =INDEX(D13:F13,MATCH($B$4,$D$9:$F$9,0)) -> 1.15 | H13: [4] | I13: A measure of how efficiently GPU's consume energy, accounting for cooling, power conversion/distribtion losses, and overhead. Lower rate is more efficient. PUE = total facility electricity / IT electricity.
A14: 5 | B14: Compute price P0 (year-1, today) | C14: $/GPU-hr | D14: 4 | E14: 5.7 | F14: 9 | G14: =INDEX(D14:F14,MATCH($B$4,$D$9:$F$9,0)) -> 5.7 | H14: [5] | I14: P0 = year-1 realized committed rate (NOT a hold-average); ENTRY price = P0×(1−decline)^TTP, then erodes toward the floor. On-demand ≈ $6.85.
A15: 6 | B15: Paid occupancy (Deal type) | C15: % | D15: =$G$45 -> 0.88 | E15: =$G$45 -> 0.88 | F15: =$G$45 -> 0.88 | G15: =$G$45 -> 0.88 | H15: [6] | I15: -
A16: 7 | B16: GPU economic life | C16: yr | D16: 3 | E16: 5 | F16: 6 | G16: =INDEX(D16:F16,MATCH($B$4,$D$9:$F$9,0)) -> 5 | H16: [7] | I16: -
A17: 8 | B17: Fixed O&M (incl. water/staff) | C17: $m/MW/yr | D17: 0.9 | E17: 0.7 | F17: 0.5 | G17: =INDEX(D17:F17,MATCH($B$4,$D$9:$F$9,0)) -> 0.7 | H17: [33] | I17: -
A18: 9 | B18: Facility salvage (% of facility capex — PRE-TAX terminal proceeds on shell + live interconnection; no recapture/gain tax) | C18: % | D18: 0.4 | E18: 0.45 | F18: 0.55 | G18: =INDEX(D18:F18,MATCH($B$4,$D$9:$F$9,0)) -> 0.45 | H18: [31] | I18: 45% blended residual: durable powered shell + interconnection (30+yr, appreciating) holds most value; cooling/fit-out depreciates faster. Modelled as PRE-TAX proceeds (no recapture/gain tax on shell); GPU salvage is after-tax — see Limitations.
A19: 10 | B19: GPU salvage (% of GPU capex, recovered at exit — spent accelerators) | C19: % | D19: 0.1 | E19: 0.1 | F19: 0.1 | G19: =INDEX(D19:F19,MATCH($B$4,$D$9:$F$9,0)) -> 0.1 | H19: [31] | I19: 10% GPU residual at 5-yr exit — conservative. Accelerators cascade (frontier yr1–2 → inference yr3–4 → batch yr5–6): ~50–60% at 3yr, collapsing to ~10% by yr5.
A20: 11 | B20: Operating hold (yr = GPU life, single flip) | C20: yr | D20: =$G$16 -> 5 | E20: =$G$16 -> 5 | F20: =$G$16 -> 5 | G20: =$G$16 -> 5 | H20: - | I20: Derived from GPU economic life; energization/GPU install period.
A21: 12 | B21: IT load | C21: MW | D21: 100 | E21: 100 | F21: 100 | G21: =INDEX(D21:F21,MATCH($B$4,$D$9:$F$9,0)) -> 100 | H21: - | I21: Design choice
A22: 13 | B22: Delivered power | C22: $/MWh | D22: =INDEX($C$50:$C$54,MATCH($B$5,$B$50:$B$54,0)) -> 80 | E22: =INDEX($D$50:$D$54,MATCH($B$5,$B$50:$B$54,0)) -> 52 | F22: =INDEX($E$50:$E$54,MATCH($B$5,$B$50:$B$54,0)) -> 30 | G22: =INDEX(D22:F22,MATCH($B$4,$D$9:$F$9,0)) -> 52 | H22: [22][23][37] | I22: source and confidence documented in "Calculations"
A23: 14 | B23: Time-to-power | C23: yr | D23: =INDEX($F$50:$F$54,MATCH($B$5,$B$50:$B$54,0)) -> 2.5911111 | E23: =INDEX($G$50:$G$54,MATCH($B$5,$B$50:$B$54,0)) -> 2 | F23: =INDEX($H$50:$H$54,MATCH($B$5,$B$50:$B$54,0)) -> 1.4088889 | G23: =INDEX(D23:F23,MATCH($B$4,$D$9:$F$9,0)) -> 2 | H23: [24][25][26][27][28][46] | I23: source and confidence documented in "Calculations"
A24: 15 | B24: Cost of capital — unlevered project hurdle rate (rf + country-risk premium; a WACC proxy, not a levered WACC) | C24: % | D24: =INDEX($I$50:$I$54,MATCH($B$5,$B$50:$B$54,0)) -> 0.0784 | E24: =INDEX($J$50:$J$54,MATCH($B$5,$B$50:$B$54,0)) -> 0.0634 | F24: =INDEX($K$50:$K$54,MATCH($B$5,$B$50:$B$54,0)) -> 0.0584 | G24: =INDEX(D24:F24,MATCH($B$4,$D$9:$F$9,0))+$G$46 -> 0.0634 | H24: [20][21] | I24: source and confidence documented in "Calculations"
I25: -
A26: 17 | B26: Corporate tax rate | C26: % | D26: =INDEX($L$50:$L$54,MATCH($B$5,$B$50:$B$54,0)) -> 0.22 | E26: =INDEX($L$50:$L$54,MATCH($B$5,$B$50:$B$54,0)) -> 0.22 | F26: =INDEX($L$50:$L$54,MATCH($B$5,$B$50:$B$54,0)) -> 0.22 | G26: =INDEX(D26:F26,MATCH($B$4,$D$9:$F$9,0)) -> 0.22 | H26: [29] | I26: source and confidence documented in "Calculations"
A27: Secondary assumptions — Low materiality (standard conventions; single value each) | I27: -
B28: Hours per year | C28: h | F28: 8760 | H28: - | I28: 8760 h/yr
B29: Unit scale ($ per $m) | C29: $ | F29: 1000000 | H29: - | I29: $1m = 1,000,000
B30: Insurance rate (x GPU capex) | C30: % | F30: 0.004 | H30: [43] | I30: 0.4% of GPU capex (Hotaling/Lockton operating insurance).
B31: Property tax abatement ((1-abate) applied) | C31: % | F31: 0.5 | H31: [29] | I31: -
B32: Ramp yr-1 occupancy (% of steady) | C32: % | F32: 0.65 | H32: [32] | I32: -
B33: Ramp yr-2 occupancy (% of steady) | C33: % | F33: 0.85 | H33: [32] | I33: -
B34: Facility life (sense-check only) | C34: yr | F34: 15 | H34: - | I34: deprec uses shell/fit-out below
B35: Shell fraction of facility capex | C35: % | F35: 0.45 | H35: [43] | I35: -
B36: Shell / building life | C36: yr | F36: 25 | H36: [43] | I36: -
B37: AI fit-out life (cooling/MEP) | C37: yr | F37: 12 | H37: [43] | I37: -
B38: Idle-shell holding cost (%/yr facility capex, wait) | C38: % | F38: 0.015 | H38: [14] | I38: -
B39: USD risk-free rate (10-yr Treasury; feeds WACC) | C39: % | F39: 0.04236 | H39: [21] | I39: US 10-yr 4.466% 90-day avg (FRED DGS10) − US default 0.23% (Damodaran) = USD risk-free.
B40: Shadow carbon price (context lens; not in P&L) | C40: $/tCO₂ | F40: 190 | H40: [47] | I40: US EPA 2023 social cost of carbon ≈ $190/t (2020$, ~2% near-term); EU ETS ≈ $80/t alternative. Editable. Context lens only — priced in the Comparison carbon-adjusted view, excluded from the core NPV.
A44: Deal structure — Contracted vs Merchant | C44: Contracted | D44: Merchant | G44: Active | I44: Contracted=anchor offtake (low WACC, high occ); Merchant=speculative (WACC premium, lower occ).
B45: Paid occupancy | C45: 0.88 | D45: 0.7 | G45: =INDEX(C45:D45,MATCH($B$7,$C$44:$D$44,0)) -> 0.88 | H45: [6] | I45: -
...

Sheet ▸ CALCULATIONS
A1: ▸ CALCULATIONS

Sheet Capex Stack
A1: Capex Stack — per MW build-up ($m/MW, active country) | C1: =IF(Checks!$C$4>0,"MODEL IN ERROR","checks OK") -> checks OK
A2: Total capex/MW decomposed into sourced layers. In-rack networking (NVLink/switching) is carried inside the rack-allocated GPU+IT figure (SemiAnalysis). Reconciles to the Unit Economics per-MW Base total.
B4: Layer | C4: $m/MW | D4: Basis / source | E4: Notes / basis
B5: Shell / building (45% of facility, Base) | C5: =Assumptions!$F$35*Assumptions!$E$10 -> 7.65 | D5: [1] | E5: Shell/building 45% of facility; life 25yr (McKinsey/dgtlinfra)
B6: Fit-out — cooling/MEP (55% of facility, Base) | C6: =(1-Assumptions!$F$35)*Assumptions!$E$10 -> 9.35 | D6: [1] | E6: Fit-out cooling/MEP 55% of facility; life 12yr (liquid-cooled AI)
B7: GPU + in-rack IT/networking (per MW) | C7: =Assumptions!$G$12*Assumptions!$E$11/Unit_scale -> 25.2 | D7: [2] | E7: SemiAnalysis Blackwell B200 server BOM ($42k/GPU × 600/MW)
B8: Interconnection (active country) | C8: =INDEX(Assumptions!$N$50:$N$54,MATCH(Assumptions!$B$5,Assumptions!$B$50:$B$54,0)) -> 0.4 | D8: [8][9][10][11][12] | E8: Country cards — per-country interconnection ($m/MW)
B9: Total capex per MW (stack) | C9: =SUM(C5:C8) -> 42.6
B10: Unit Economics Base capex/MW | C10: ='Unit Economics'!$C$15 -> 42.6
B11: Reconciliation gap (must be 0) | C11: =C9-C10 -> 0

Sheet Unit Economics
A1: Unit Economics — one megawatt of IT load (bottom-up build block) | C1: =IF(Checks!$C$4>0,"MODEL IN ERROR","checks OK") -> checks OK
A2: The atomic build unit. Everything scales linearly from here: totals = per-MW × IT load. Blue = linked from Assumptions; black = calculated. Rows 14–15 are tied to independent benchmarks (external anchor).
B3: Item | C3: Value | D3: Low | E3: High | F3: Units | G3: Note | H3: Source
B4: GPUs per MW (active) | C4: =Assumptions!$G$12 -> 600 | F4: #/MW | G4: NVIDIA B200 / HGX B200 datasheet | H4: [3][17]
B5: GPU + IT capex per GPU (active) | C5: =Assumptions!$G$11 -> 42000 | F5: $/GPU | G5: SemiAnalysis rack-allocated | H5: [2]
B6: Compute price (active) | C6: =Assumptions!$G$14 -> 5.7 | F6: $/GPU-hr | G6: Triangulated | H6: [5]
B7: Paid occupancy (deal) | C7: =Paid_occupancy -> 0.88 | F7: % | G7: Deal structure
B8: Facility capex per MW (active, ex-interconnect) | C8: =Facility_capex_MW -> 17 | F8: $m/MW | G8: AI liquid-cooled 2026 | H8: [1]
B9: Interconnection per MW (active country) | C9: =INDEX(Assumptions!$N$50:$N$54,MATCH(Assumptions!$B$5,Assumptions!$B$50:$B$54,0)) -> 0.4 | F9: $m/MW | G9: Country cards | H9: [8][9][10][11][12]
B10: — GPU capex per MW (active) | C10: =C4*C5/Unit_scale -> 25.2 | F10: $m/MW | G10: GPUs/MW × $/GPU
B11: — Revenue per MW/yr (active) | C11: =C4*C6*Hours_per_year*C7/Unit_scale -> 26.364096 | F11: $m/MW/yr | G11: GPUs/MW × price × hrs × occ
B12: Total capex per MW (active) — rolls up to totals | C12: =C8+C9+C10 -> 42.6 | F12: $m/MW | G12: facility + interconnect + GPU (per MW)
B14: External anchor — BASE case tied to independent benchmarks (toggle-invariant) | F14: (errors only if Base leaves the sourced band — scenarios legitimately flex outside it)
B15: Base total capex per MW | C15: =Assumptions!$E$10+C9+Assumptions!$G$12*Assumptions!$E$11/Unit_scale -> 42.6 | D15: 30 | E15: 50 | F15: $m/MW | G15: ANCHOR: independent DC all-in capex $30–50m/MW (SemiAnalysis Blackwell BOM / CBRE build cost) | H15: [15]
B16: Base revenue per MW/yr | C16: =Assumptions!$G$12*Assumptions!$E$14*Hours_per_year*Paid_occupancy/Unit_scale -> 26.364096 | D16: 15 | E16: 40 | F16: $m/MW/yr | G16: ANCHOR: hyperscale colo revenue $15–40m/MW/yr (SemiAnalysis rental index × density) | H16: [16]
B18: Roll-up reconciliation (active per-MW × IT load must tie to Calculations)
B19: Total capex per MW (active) × IT load | C19: =C12*IT_load_MW -> 4260
B20: Calculations facility + GPU capex | C20: =Calculations!$C$7+Calculations!$C$6 -> 4260
B21: Reconciliation gap (must be 0) | C21: =C19-C20 -> 0

Sheet Buildout Schedule
A1: Buildout Schedule — facility-capex draw & reconciliation | C1: =IF(Checks!$C$4>0,"MODEL IN ERROR","checks OK") -> checks OK
A2: Facility capex is drawn evenly across the pre-power build (periods 0..S−1); GPUs are bought in full at energisation. The former 4-phase display was removed (Aug 2026): it did not feed the DCF and could be misread as a rival schedule. DCF timing comes from the draw schedule below; the reconciliation (H3) ties the DCF’s realised facility-capex line to the capex driver.
E3: Reconciliation gap (must be 0): | H3: =ABS(SUM(Calculations!D48:W48)+Calculations!C7)+C18 -> 0
A13: Facility-capex DRAW schedule — active country: this is the TIMING the Calculations timeline reads (row 16). Facility capex is disbursed evenly across the build (periods 0..S−1), not all at t=0; GPU capex lands at ops-start.
A14: Ops start S (active, = ROUND(TTP)) | C14: =ROUND(Assumptions!$G$23,0) -> 2
A15: Period | D15: 0 | E15: 1 | F15: 2 | G15: 3 | H15: 4 | I15: 5 | J15: 6 | K15: 7 | L15: 8 | M15: 9 | N15: 10 | O15: 11 | P15: 12 | Q15: 13 | R15: 14 | S15: 15 | T15: 16 | U15: 17 | V15: 18 | W15: 19
A16: Draw weight (feeds Calculations!row48) | D16: =IF($C$14=0,--(D15=0),--(D15<=$C$14-1)/$C$14) -> 0.5 | E16: =IF($C$14=0,--(E15=0),--(E15<=$C$14-1)/$C$14) -> 0.5 | F16: =IF($C$14=0,--(F15=0),--(F15<=$C$14-1)/$C$14) -> 0 | G16: =IF($C$14=0,--(G15=0),--(G15<=$C$14-1)/$C$14) -> 0 | H16: =IF($C$14=0,--(H15=0),--(H15<=$C$14-1)/$C$14) -> 0 | I16: =IF($C$14=0,--(I15=0),--(I15<=$C$14-1)/$C$14) -> 0 | J16: =IF($C$14=0,--(J15=0),--(J15<=$C$14-1)/$C$14) -> 0 | K16: =IF($C$14=0,--(K15=0),--(K15<=$C$14-1)/$C$14) -> 0 | ... W16: =IF($C$14=0,--(W15=0),--(W15<=$C$14-1)/$C$14) -> 0
A17: Draw ($m) | D17: =D16*$C$19 -> 870 | E17: =E16*$C$19 -> 870 | F17: =F16*$C$19 -> 0 | G17: =G16*$C$19 -> 0 | H17: =H16*$C$19 -> 0 | I17: =I16*$C$19 -> 0 | J17: =J16*$C$19 -> 0 | K17: =K16*$C$19 -> 0 | ... W17: =W16*$C$19 -> 0
A18: Draw schedule reconciles (weights sum to 1, $m sum to facility) — must be 0 | C18: =ABS(SUM(D16:W16)-1)+ABS(SUM(D17:W17)-C19) -> 0
A19: Facility capex total ($m) | C19: =('Unit Economics'!$C$8+'Unit Economics'!$C$9)*IT_load_MW -> 1740
A21: Assumption — facility draw profile: capex is spread EVENLY across the pre-power build (periods 0..S−1), GPUs purchased in full at energisation (ops-start). Modelling convention, not a separately toggled input.
A22: Assumption — ops-start uses integer periods: S = ROUND(time-to-power). Fractional-year queues round to the nearest annual period (e.g., 4.5 yr → period 5). Annual granularity is a deliberate simplification.

Sheet Calculations
A1: ="Calculations — "&Assumptions!$B$5&" ("&Assumptions!$B$4&")" -> Calculations — Norway (Base) | C1: =IF(Checks!$C$4>0,"MODEL IN ERROR","checks OK") -> checks OK
A2: Single-country DCF for the selected country/scenario: annual feeders, then the per-period cash-flow statement, then outputs. Blue = value linked in from Assumptions; black = calculated here. All $m.
A4: Single-country aggregates (annual, active country/scenario) — feed the statement below
A5: Number of GPUs | B5: # | C5: =IT_load_MW*Assumptions!$G$12 -> 60000
A6: GPU capex | B6: $m | C6: =C5*Assumptions!$G$11/Unit_scale -> 2520
A7: Facility capex (incl. interconnect) | B7: $m | C7: =IT_load_MW*Facility_capex_MW+IT_load_MW*INDEX(Assumptions!$N$50:$N$54,MATCH(Assumptions!$B$5,Assumptions!$B$50:$B$54,0)) -> 1740
A8: Total power draw | B8: MW | C8: =IT_load_MW*Assumptions!$G$13 -> 115
A9: Annual revenue | B9: $m | C9: =C5*Assumptions!$G$14*Hours_per_year*Paid_occupancy/Unit_scale -> 2636.4096
A10: Annual power cost | B10: $m | C10: =C8*Hours_per_year*Assumptions!$G$22*Paid_occupancy/Unit_scale -> 46.098624
A11: Insurance ($m/yr) | B11: $m | C11: =Insurance_rate*C6 -> 10.08
A12: Property tax ($m/yr) | B12: $m | C12: =INDEX(Assumptions!$O$50:$O$54,MATCH(Assumptions!$B$5,Assumptions!$B$50:$B$54,0))*(C7+C6)*(1-Prop_tax_abatement) -> 6.39
A13: Annual opex (O&M+ins+proptax) | B13: $m | C13: =IT_load_MW*OM_fixed+C11+C12 -> 86.47
A14: Annual EBITDA | B14: $m | C14: =C9-C10-C13 -> 2503.841
A15: Facility deprec rate (blended shell/fit-out) | B15: x | C15: =Assumptions!$F$35/Assumptions!$F$36+(1-Assumptions!$F$35)/Assumptions!$F$37 -> 0.063833333
A16: Annual depreciation | B16: $m | C16: =C6/GPU_life+C7*C15 -> 615.07
A17: After-tax annual op. CF (steady) | B17: $m | C17: =C14-Assumptions!$G$26*MAX(C14-C16,0) -> 2088.3114
A18: Occupancy-linked after-tax margin | B18: $m | C18: =(C9-C10)*(1-Assumptions!$G$26) -> 2020.4426
A19: Terminal value (reference) | B19: $m | C19: =C7*Facility_salvage_pct+C6*GPU_salvage_pct -> 1035
A20: Ops start period | B20: yr | C20: =ROUND(Assumptions!$G$23,0) -> 2
A21: Discount base v = 1/(1+WACC) | B21: x | C21: =1/(1+Assumptions!$G$24) -> 0.94037991
A22: Ramp PV haircut | B22: $m | C22: =C18*((1-Ramp_yr1)*C21^(C20)+(1-Ramp_yr2)*C21^(C20+1)) -> 877.37467
A23: Revenue per unit util | B23: $m | C23: =C5*Assumptions!$G$14*Hours_per_year/Unit_scale -> 2995.92
A24: Power per unit util | B24: $m | C24: =C8*Hours_per_year*Assumptions!$G$22/Unit_scale -> 52.3848
A26: Phased facility capex: even draw over the build (periods 0..S−1); GPU capex at ops-start. Both feed the statement below (see Buildout Schedule).
A34: Per-period cash-flow statement (periods 0–19). Revenue uses the per-period compute-price path: entry = P0·(1−decline)^TTP, then Contracted holds it flat while Merchant keeps eroding to the floor.
A35: Line item | B35: Units | D35: 0 | E35: 1 | F35: 2 | G35: 3 | H35: 4 | I35: 5 | J35: 6 | K35: 7 | L35: 8 | M35: 9 | N35: 10 | O35: 11 | P35: 12 | Q35: 13 | R35: 14 | S35: 15 | T35: 16 | U35: 17 | V35: 18 | W35: 19 | X35: Check
A36: Period counter | B36: # | D36: 0 | E36: =D36+1 -> 1 | F36: =E36+1 -> 2 | G36: =F36+1 -> 3 | H36: =G36+1 -> 4 | I36: =H36+1 -> 5 | J36: =I36+1 -> 6 | K36: =J36+1 -> 7 | L36: =K36+1 -> 8 | ... W36: =V36+1 -> 19
A37: Operating year? (1 = in ops) | B37: flag | D37: =--(D56>0) -> 0 | E37: =--(E56>0) -> 0 | F37: =--(F56>0) -> 1 | G37: =--(G56>0) -> 1 | H37: =--(H56>0) -> 1 | I37: =--(I56>0) -> 1 | J37: =--(J56>0) -> 1 | K37: =--(K56>0) -> 0 | ... W37: =--(W56>0) -> 0 | X37: =--(SUM(D37:W37)<>GPU_life) -> 0
A38: Occupancy factor (lease-up ramp) | B38: x | D38: =D37*(1-(1-Ramp_yr1)*((D36-$C$20-MAX(D56-1,0)*GPU_life)=0)-(1-Ramp_yr2)*((D36-$C$20-MAX(D56-1,0)*GPU_life)=1)) -> 0 | E38: =E37*(1-(1-Ramp_yr1)*((E36-$C$20-MAX(E56-1,0)*GPU_life)=0)-(1-Ramp_yr2)*((E36-$C$20-MAX(E56-1,0)*GPU_life)=1)) -> 0 | F38: =F37*(1-(1-Ramp_yr1)*((F36-$C$20-MAX(F56-1,0)*GPU_life)=0)-(1-Ramp_yr2)*((F36-$C$20-MAX(F56-1,0)*GPU_life)=1)) -> 0.65 | G38: =G37*(1-(1-Ramp_yr1)*((G36-$C$20-MAX(G56-1,0)*GPU_life)=0)-(1-Ramp_yr2)*((G36-$C$20-MAX(G56-1,0)*GPU_life)=1)) -> 0.85 | H38: =H37*(1-(1-Ramp_yr1)*((H36-$C$20-MAX(H56-1,0)*GPU_life)=0)-(1-Ramp_yr2)*((H36-$C$20-MAX(H56-1,0)*GPU_life)=1)) -> 1 | I38: =I37*(1-(1-Ramp_yr1)*((I36-$C$20-MAX(I56-1,0)*GPU_life)=0)-(1-Ramp_yr2)*((I36-$C$20-MAX(I56-1,0)*GPU_life)=1)) -> 1 | J38: =J37*(1-(1-Ramp_yr1)*((J36-$C$20-MAX(J56-1,0)*GPU_life)=0)-(1-Ramp_yr2)*((J36-$C$20-MAX(J56-1,0)*GPU_life)=1)) -> 1 | K38: =K37*(1-(1-Ramp_yr1)*((K36-$C$20-MAX(K56-1,0)*GPU_life)=0)-(1-Ramp_yr2)*((K36-$C$20-MAX(K56-1,0)*GPU_life)=1)) -> 0 | ... W38: =W37*(1-(1-Ramp_yr1)*((W36-$C$20-MAX(W56-1,0)*GPU_life)=0)-(1-Ramp_yr2)*((W36-$C$20-MAX(W56-1,0)*GPU_life)=1)) -> 0
A39: Compute price this period | B39: $/GPU-hr | D39: =IF(Assumptions!$B$7="Contracted",MAX(Price_floor,Compute_P0*(1-Price_decline)^(Assumptions!$G$23+MAX(D56-1,0)*GPU_life)),MAX(Price_floor,Compute_P0*(1-Price_decline)^MAX(Assumptions!$G$23+D36-$C$20))) -> 3.648 | E39: =IF(Assumptions!$B$7="Contracted",MAX(Price_floor,Compute_P0*(1-Price_decline)^(Assumptions!$G$23+MAX(E56-1,0)*GPU_life)),MAX(Price_floor,Compute_P0*(1-Price_decline)^MAX(Assumptions!$G$23+E36-$C$20))) -> 3.648 | F39: =IF(Assumptions!$B$7="Contracted",MAX(Price_floor,Compute_P0*(1-Price_decline)^(Assumptions!$G$23+MAX(F56-1,0)*GPU_life)),MAX(Price_floor,Compute_P0*(1-Price_decline)^MAX(Assumptions!$G$23+F36-$C$20))) -> 3.648 | G39: =IF(Assumptions!$B$7="Contracted",MAX(Price_floor,Compute_P0*(1-Price_decline)^(Assumptions!$G$23+MAX(G56-1,0)*GPU_life)),MAX(Price_floor,Compute_P0*(1-Price_decline)^MAX(Assumptions!$G$23+G36-$C$20))) -> 3.648 | H39: =IF(Assumptions!$B$7="Contracted",MAX(Price_floor,Compute_P0*(1-Price_decline)^(Assumptions!$G$23+MAX(H56-1,0)*GPU_life)),MAX(Price_floor,Compute_P0*(1-Price_decline)^MAX(Assumptions!$G$23+H36-$C$20))) -> 3.648 | I39: =IF(Assumptions!$B$7="Contracted",MAX(Price_floor,Compute_P0*(1-Price_decline)^(Assumptions!$G$23+MAX(I56-1,0)*GPU_life)),MAX(Price_floor,Compute_P0*(1-Price_decline)^MAX(Assumptions!$G$23+I36-$C$20))) -> 3.648 | J39: =IF(Assumptions!$B$7="Contracted",MAX(Price_floor,Compute_P0*(1-Price_decline)^(Assumptions!$G$23+MAX(J56-1,0)*GPU_life)),MAX(Price_floor,Compute_P0*(1-Price_decline)^MAX(Assumptions!$G$23+J36-$C$20))) -> 3.648 | K39: =IF(Assumptions!$B$7="Contracted",MAX(Price_floor,Compute_P0*(1-Price_decline)^(Assumptions!$G$23+MAX(K56-1,0)*GPU_life)),MAX(Price_floor,Compute_P0*(1-Price_decline)^MAX(Assumptions!$G$23+K36-$C$20))) -> 3.648 | ... W39: =IF(Assumptions!$B$7="Contracted",MAX(Price_floor,Compute_P0*(1-Price_decline)^(Assumptions!$G$23+MAX(W56-1,0)*GPU_life)),MAX(Price_floor,Compute_P0*(1-Price_decline)^MAX(Assumptions!$G$23+W36-$C$20))) -> 3.648
A40: Revenue (price × occupancy) | B40: $m | D40: =$C$9*D39/Compute_P0*D38 -> 0 | E40: =$C$9*E39/Compute_P0*E38 -> 0 | F40: =$C$9*F39/Compute_P0*F38 -> 1096.7464 | G40: =$C$9*G39/Compute_P0*G38 -> 1434.2068 | H40: =$C$9*H39/Compute_P0*H38 -> 1687.3021 | I40: =$C$9*I39/Compute_P0*I38 -> 1687.3021 | J40: =$C$9*J39/Compute_P0*J38 -> 1687.3021 | K40: =$C$9*K39/Compute_P0*K38 -> 0 | ... W40: =$C$9*W39/Compute_P0*W38 -> 0 | X40: =--(SUMPRODUCT(--(D40:W40<0))>0) -> 0
A41: Power cost | B41: $m | D41: =-$C$10*D38 -> 0 | E41: =-$C$10*E38 -> 0 | F41: =-$C$10*F38 -> -29.964106 | G41: =-$C$10*G38 -> -39.18383 | H41: =-$C$10*H38 -> -46.098624 | I41: =-$C$10*I38 -> -46.098624 | J41: =-$C$10*J38 -> -46.098624 | K41: =-$C$10*K38 -> 0 | ... W41: =-$C$10*W38 -> 0
A42: O&M + insurance + property tax | B42: $m | D42: =-$C$13*D37 -> 0 | E42: =-$C$13*E37 -> 0 | F42: =-$C$13*F37 -> -86.47 | G42: =-$C$13*G37 -> -86.47 | H42: =-$C$13*H37 -> -86.47 | I42: =-$C$13*I37 -> -86.47 | J42: =-$C$13*J37 -> -86.47 | K42: =-$C$13*K37 -> 0 | ... W42: =-$C$13*W37 -> 0
A43: EBITDA | B43: $m | D43: =D40+D41+D42 -> 0 | E43: =E40+E41+E42 -> 0 | F43: =F40+F41+F42 -> 980.31229 | G43: =G40+G41+G42 -> 1308.553 | H43: =H40+H41+H42 -> 1554.7335 | I43: =I40+I41+I42 -> 1554.7335 | J43: =J40+J41+J42 -> 1554.7335 | K43: =K40+K41+K42 -> 0 | ... W43: =W40+W41+W42 -> 0
A44: Depreciation | B44: $m | D44: =-($C$7*$C$15+$C$6/GPU_life)*D37 -> 0 | E44: =-($C$7*$C$15+$C$6/GPU_life)*E37 -> 0 | F44: =-($C$7*$C$15+$C$6/GPU_life)*F37 -> -615.07 | G44: =-($C$7*$C$15+$C$6/GPU_life)*G37 -> -615.07 | H44: =-($C$7*$C$15+$C$6/GPU_life)*H37 -> -615.07 | I44: =-($C$7*$C$15+$C$6/GPU_life)*I37 -> -615.07 | J44: =-($C$7*$C$15+$C$6/GPU_life)*J37 -> -615.07 | K44: =-($C$7*$C$15+$C$6/GPU_life)*K37 -> 0 | ... W44: =-($C$7*$C$15+$C$6/GPU_life)*W37 -> 0
A45: Taxable income (EBIT) | B45: $m | D45: =D43+D44 -> 0 | E45: =E43+E44 -> 0 | F45: =F43+F44 -> 365.24229 | G45: =G43+G44 -> 693.48299 | H45: =H43+H44 -> 939.66352 | I45: =I43+I44 -> 939.66352 | J45: =J43+J44 -> 939.66352 | K45: =K43+K44 -> 0 | ... W45: =W43+W44 -> 0
A46: Tax (no loss refund) | B46: $m | D46: =-Assumptions!$G$26*MAX(D45,0) -> 0 | E46: =-Assumptions!$G$26*MAX(E45,0) -> 0 | F46: =-Assumptions!$G$26*MAX(F45,0) -> -80.353303 | G46: =-Assumptions!$G$26*MAX(G45,0) -> -152.56626 | H46: =-Assumptions!$G$26*MAX(H45,0) -> -206.72597 | I46: =-Assumptions!$G$26*MAX(I45,0) -> -206.72597 | J46: =-Assumptions!$G$26*MAX(J45,0) -> -206.72597 | K46: =-Assumptions!$G$26*MAX(K45,0) -> 0 | ... W46: =-Assumptions!$G$26*MAX(W45,0) -> 0
A47: After-tax operating CF | B47: $m | D47: =D43+D46 -> 0 | E47: =E43+E46 -> 0 | F47: =F43+F46 -> 899.95898 | G47: =G43+G46 -> 1155.9867 | H47: =H43+H46 -> 1348.0075 | I47: =I43+I46 -> 1348.0075 | J47: =J43+J46 -> 1348.0075 | K47: =K43+K46 -> 0 | ... W47: =W43+W46 -> 0
A48: Facility capex (phased over build) | B48: $m | D48: =-$C$7*'Buildout Schedule'!D16 -> -870 | E48: =-$C$7*'Buildout Schedule'!E16 -> -870 | F48: =-$C$7*'Buildout Schedule'!F16 -> 0 | G48: =-$C$7*'Buildout Schedule'!G16 -> 0 | H48: =-$C$7*'Buildout Schedule'!H16 -> 0 | I48: =-$C$7*'Buildout Schedule'!I16 -> 0 | J48: =-$C$7*'Buildout Schedule'!J16 -> 0 | K48: =-$C$7*'Buildout Schedule'!K16 -> 0 | ... W48: =-$C$7*'Buildout Schedule'!W16 -> 0
A49: Holding cost (idle shell, pre-power) | B49: $m | D49: =-$C$7*Assumptions!$F$38*IF(AND(D36>=1,D36<=$C$20),1,0) -> 0 | E49: =-$C$7*Assumptions!$F$38*IF(AND(E36>=1,E36<=$C$20),1,0) -> -26.1 | F49: =-$C$7*Assumptions!$F$38*IF(AND(F36>=1,F36<=$C$20),1,0) -> -26.1 | G49: =-$C$7*Assumptions!$F$38*IF(AND(G36>=1,G36<=$C$20),1,0) -> 0 | H49: =-$C$7*Assumptions!$F$38*IF(AND(H36>=1,H36<=$C$20),1,0) -> 0 | I49: =-$C$7*Assumptions!$F$38*IF(AND(I36>=1,I36<=$C$20),1,0) -> 0 | J49: =-$C$7*Assumptions!$F$38*IF(AND(J36>=1,J36<=$C$20),1,0) -> 0 | K49: =-$C$7*Assumptions!$F$38*IF(AND(K36>=1,K36<=$C$20),1,0) -> 0 | ... W49: =-$C$7*Assumptions!$F$38*IF(AND(W36>=1,W36<=$C$20),1,0) -> 0
...

Sheet Country Engine
A1: Country Engine — every country × deal, per period (identical method to Calculations) | C1: =IF(Checks!$C$4>0,"MODEL IN ERROR","checks OK") -> checks OK
A2: Each country's full 20-period cash flow, computed BOTH deal types, so the multi-country and both-deal NPVs use the SAME method as the single-country drill — the closed-form that could out-run the grid is retired. Feeds Comparison (active deal) and Deal Comparison (both). All $m.
A3: Period index | D3: 0 | E3: 1 | F3: 2 | G3: 3 | H3: 4 | I3: 5 | J3: 6 | K3: 7 | L3: 8 | M3: 9 | N3: 10 | O3: 11 | P3: 12 | Q3: 13 | R3: 14 | S3: 15 | T3: 16 | U3: 17 | V3: 18 | W3: 19
A5: ── Norway · Contracted ── | B5: Norway
A6: Ops start S (yr) | C6: =ROUND($C$27,0) -> 2
A7: WACC (incl deal) | C7: =INDEX(Assumptions!$I$50:$K$54,$C$11,MATCH(Assumptions!$B$4,Assumptions!$D$9:$F$9,0))+Assumptions!$C$46 -> 0.0634
A8: Discount base v | C8: =1/(1+$C$7) -> 0.94037991
A9: Power cost (full occ) $m | C9: =IT_load_MW*INDEX(Assumptions!$M$50:$M$54,$C$11,1)*Hours_per_year*INDEX(Assumptions!$C$50:$E$54,$C$11,MATCH(Assumptions!$B$4,Assumptions!$D$9:$F$9,0))*Assumptions!$C$45/Unit_scale -> 46.098624
A10: Opex $m | C10: =IT_load_MW*OM_fixed+Insurance_rate*Calculations!$C$6+INDEX(Assumptions!$O$50:$O$54,$C$11,1)*($C$13+Calculations!$C$6)*(1-Prop_tax_abatement) -> 86.47
A11: country row index | C11: =MATCH($B$5,Assumptions!$B$50:$B$54,0) -> 1
A12: Tax rate | C12: =INDEX(Assumptions!$L$50:$L$54,MATCH($B$5,Assumptions!$B$50:$B$54,0),1) -> 0.22
A13: Facility capex $m | C13: =IT_load_MW*(Facility_capex_MW+INDEX(Assumptions!$N$50:$N$54,$C$11,1)) -> 1740
A14: GPU capex $m | C14: =Calculations!$C$6 -> 2520
A15: Year-1 full revenue $m | C15: =IT_load_MW*Assumptions!$G$12*Hours_per_year*Assumptions!$C$45/Unit_scale*Compute_P0 -> 2636.4096
A16: operating flag | D16: =IF(D$3<$C$6,0,IF(D$3<=$C$6+GPU_life-1,1,0)) -> 0 | E16: =IF(E$3<$C$6,0,IF(E$3<=$C$6+GPU_life-1,1,0)) -> 0 | F16: =IF(F$3<$C$6,0,IF(F$3<=$C$6+GPU_life-1,1,0)) -> 1 | G16: =IF(G$3<$C$6,0,IF(G$3<=$C$6+GPU_life-1,1,0)) -> 1 | H16: =IF(H$3<$C$6,0,IF(H$3<=$C$6+GPU_life-1,1,0)) -> 1 | I16: =IF(I$3<$C$6,0,IF(I$3<=$C$6+GPU_life-1,1,0)) -> 1 | J16: =IF(J$3<$C$6,0,IF(J$3<=$C$6+GPU_life-1,1,0)) -> 1 | K16: =IF(K$3<$C$6,0,IF(K$3<=$C$6+GPU_life-1,1,0)) -> 0 | ... W16: =IF(W$3<$C$6,0,IF(W$3<=$C$6+GPU_life-1,1,0)) -> 0
A17: flag | D17: =--(D16>0) -> 0 | E17: =--(E16>0) -> 0 | F17: =--(F16>0) -> 1 | G17: =--(G16>0) -> 1 | H17: =--(H16>0) -> 1 | I17: =--(I16>0) -> 1 | J17: =--(J16>0) -> 1 | K17: =--(K16>0) -> 0 | ... W17: =--(W16>0) -> 0
A18: occupancy | D18: =D17*(1-(1-Ramp_yr1)*((D$3-$C$6)=0)-(1-Ramp_yr2)*((D$3-$C$6)=1)) -> 0 | E18: =E17*(1-(1-Ramp_yr1)*((E$3-$C$6)=0)-(1-Ramp_yr2)*((E$3-$C$6)=1)) -> 0 | F18: =F17*(1-(1-Ramp_yr1)*((F$3-$C$6)=0)-(1-Ramp_yr2)*((F$3-$C$6)=1)) -> 0.65 | G18: =G17*(1-(1-Ramp_yr1)*((G$3-$C$6)=0)-(1-Ramp_yr2)*((G$3-$C$6)=1)) -> 0.85 | H18: =H17*(1-(1-Ramp_yr1)*((H$3-$C$6)=0)-(1-Ramp_yr2)*((H$3-$C$6)=1)) -> 1 | I18: =I17*(1-(1-Ramp_yr1)*((I$3-$C$6)=0)-(1-Ramp_yr2)*((I$3-$C$6)=1)) -> 1 | J18: =J17*(1-(1-Ramp_yr1)*((J$3-$C$6)=0)-(1-Ramp_yr2)*((J$3-$C$6)=1)) -> 1 | K18: =K17*(1-(1-Ramp_yr1)*((K$3-$C$6)=0)-(1-Ramp_yr2)*((K$3-$C$6)=1)) -> 0 | ... W18: =W17*(1-(1-Ramp_yr1)*((W$3-$C$6)=0)-(1-Ramp_yr2)*((W$3-$C$6)=1)) -> 0
A19: price $/GPU-hr | D19: =MAX(Price_floor,Compute_P0*(1-Price_decline)^$C$27) -> 3.648 | E19: =MAX(Price_floor,Compute_P0*(1-Price_decline)^$C$27) -> 3.648 | F19: =MAX(Price_floor,Compute_P0*(1-Price_decline)^$C$27) -> 3.648 | G19: =MAX(Price_floor,Compute_P0*(1-Price_decline)^$C$27) -> 3.648 | H19: =MAX(Price_floor,Compute_P0*(1-Price_decline)^$C$27) -> 3.648 | I19: =MAX(Price_floor,Compute_P0*(1-Price_decline)^$C$27) -> 3.648 | J19: =MAX(Price_floor,Compute_P0*(1-Price_decline)^$C$27) -> 3.648 | K19: =MAX(Price_floor,Compute_P0*(1-Price_decline)^$C$27) -> 3.648 | ... W19: =MAX(Price_floor,Compute_P0*(1-Price_decline)^$C$27) -> 3.648
A20: revenue | D20: =$C$15*D19/Compute_P0*D18 -> 0 | E20: =$C$15*E19/Compute_P0*E18 -> 0 | F20: =$C$15*F19/Compute_P0*F18 -> 1096.7464 | G20: =$C$15*G19/Compute_P0*G18 -> 1434.2068 | H20: =$C$15*H19/Compute_P0*H18 -> 1687.3021 | I20: =$C$15*I19/Compute_P0*I18 -> 1687.3021 | J20: =$C$15*J19/Compute_P0*J18 -> 1687.3021 | K20: =$C$15*K19/Compute_P0*K18 -> 0 | ... W20: =$C$15*W19/Compute_P0*W18 -> 0
A21: EBITDA | D21: =D20-$C$9*D18-$C$10*D17 -> 0 | E21: =E20-$C$9*E18-$C$10*E17 -> 0 | F21: =F20-$C$9*F18-$C$10*F17 -> 980.31229 | G21: =G20-$C$9*G18-$C$10*G17 -> 1308.553 | H21: =H20-$C$9*H18-$C$10*H17 -> 1554.7335 | I21: =I20-$C$9*I18-$C$10*I17 -> 1554.7335 | J21: =J20-$C$9*J18-$C$10*J17 -> 1554.7335 | K21: =K20-$C$9*K18-$C$10*K17 -> 0 | ... W21: =W20-$C$9*W18-$C$10*W17 -> 0
A22: depreciation | D22: =-($C$13*Calculations!$C$15+$C$14/GPU_life)*D17 -> 0 | E22: =-($C$13*Calculations!$C$15+$C$14/GPU_life)*E17 -> 0 | F22: =-($C$13*Calculations!$C$15+$C$14/GPU_life)*F17 -> -615.07 | G22: =-($C$13*Calculations!$C$15+$C$14/GPU_life)*G17 -> -615.07 | H22: =-($C$13*Calculations!$C$15+$C$14/GPU_life)*H17 -> -615.07 | I22: =-($C$13*Calculations!$C$15+$C$14/GPU_life)*I17 -> -615.07 | J22: =-($C$13*Calculations!$C$15+$C$14/GPU_life)*J17 -> -615.07 | K22: =-($C$13*Calculations!$C$15+$C$14/GPU_life)*K17 -> 0 | ... W22: =-($C$13*Calculations!$C$15+$C$14/GPU_life)*W17 -> 0
